{
  "AllureSample.Sample_AllureReportTypes+TestClass.SimpleTestPassed" : {
    "statistic" : {
      "failed" : 0,
      "broken" : 0,
      "skipped" : 0,
      "passed" : 1,
      "unknown" : 0,
      "total" : 1
    },
    "items" : [ {
      "uid" : "8d507e87a4850527",
      "status" : "passed",
      "time" : {
        "start" : 1569925991249,
        "stop" : 1569925991256,
        "duration" : 7
      }
    } ]
  },
  "AllureSample.Sample_AllureReportTypes+TestClass.SimpleTestFailed" : {
    "statistic" : {
      "failed" : 1,
      "broken" : 0,
      "skipped" : 0,
      "passed" : 0,
      "unknown" : 0,
      "total" : 1
    },
    "items" : [ {
      "uid" : "154b2ebd5d6156d8",
      "status" : "failed",
      "statusDetails" : "  Expected: No Exception to be thrown\r\n  But was:  <System.Exception: I'm an exception\r\n   at AllureSample.Sample_AllureReportTypes.TestClass.<>c.<SimpleTestFailed>b__3_0() in C:\\Users\\Ajith.George\\Desktop\\STUDY\\Selenium-WebDriver\\Reporting\\NunitWithAllureReporting_Version1\\NunitWithAllureReporting_Version1\\Sample_AllureReportTypes.cs:line 54\r\n   at NUnit.Framework.Constraints.ThrowsConstraint.VoidInvocationDescriptor.Invoke()\r\n   at NUnit.Framework.Constraints.ThrowsConstraint.ExceptionInterceptor.Intercept(Object invocation)>\r\n",
      "time" : {
        "start" : 1569925991132,
        "stop" : 1569925991208,
        "duration" : 76
      }
    } ]
  },
  "AllureSample.Sample_AllureReportTypes+TestClass.TestWithSteps" : {
    "statistic" : {
      "failed" : 0,
      "broken" : 0,
      "skipped" : 0,
      "passed" : 1,
      "unknown" : 0,
      "total" : 1
    },
    "items" : [ {
      "uid" : "8eb654d57486c9f6",
      "status" : "passed",
      "time" : {
        "start" : 1569925991259,
        "stop" : 1569925993171,
        "duration" : 1912
      }
    } ]
  }
}